

  ========= 测试开始 : 20220422_180024 =========



>>> cases\

[ suite setup ] cases\
初始化 删除所有班级
suite setup fail | ('Connection aborted.', RemoteDisconnected('Remote end closed connection without response')) 
Traceback:
  File "c:\python38\lib\site-packages\urllib3\connectionpool.py", line 445, in _make_request
    six.raise_from(e, None)
  File "<string>", line 3, in raise_from
  File "c:\python38\lib\site-packages\urllib3\connectionpool.py", line 440, in _make_request
    httplib_response = conn.getresponse()
  File "c:\python38\lib\http\client.py", line 1347, in getresponse
    response.begin()
  File "c:\python38\lib\http\client.py", line 307, in begin
    version, status, reason = self._read_status()
  File "c:\python38\lib\http\client.py", line 276, in _read_status
    raise RemoteDisconnected("Remote end closed connection without"
http.client.RemoteDisconnected: Remote end closed connection without response

During handling of the above exception, another exception occurred:

Traceback (most recent call last):
  File "c:\python38\lib\site-packages\requests\adapters.py", line 439, in send
    resp = conn.urlopen(
  File "c:\python38\lib\site-packages\urllib3\connectionpool.py", line 755, in urlopen
    retries = retries.increment(
  File "c:\python38\lib\site-packages\urllib3\util\retry.py", line 532, in increment
    raise six.reraise(type(error), error, _stacktrace)
  File "c:\python38\lib\site-packages\urllib3\packages\six.py", line 769, in reraise
    raise value.with_traceback(tb)
  File "c:\python38\lib\site-packages\urllib3\connectionpool.py", line 699, in urlopen
    httplib_response = self._make_request(
  File "c:\python38\lib\site-packages\urllib3\connectionpool.py", line 445, in _make_request
    six.raise_from(e, None)
  File "<string>", line 3, in raise_from
  File "c:\python38\lib\site-packages\urllib3\connectionpool.py", line 440, in _make_request
    httplib_response = conn.getresponse()
  File "c:\python38\lib\http\client.py", line 1347, in getresponse
    response.begin()
  File "c:\python38\lib\http\client.py", line 307, in begin
    version, status, reason = self._read_status()
  File "c:\python38\lib\http\client.py", line 276, in _read_status
    raise RemoteDisconnected("Remote end closed connection without"
urllib3.exceptions.ProtocolError: ('Connection aborted.', RemoteDisconnected('Remote end closed connection without response'))

During handling of the above exception, another exception occurred:

Traceback (most recent call last):
  File "c:\python38\lib\site-packages\hytest\utils\runner.py", line 124, in execTest
    try:suite_setup()
  File "cases\__st__.py", line 6, in suite_setup
    g_cs.del_all_class()
  File "D:\study\AutoTest_education\lib\api\yjyx_class_api.py", line 90, in del_all_class
    res = self.list_class()
  File "D:\study\AutoTest_education\lib\api\yjyx_class_api.py", line 25, in list_class
    res = requests.get(g_api_url_class, params =params)
  File "c:\python38\lib\site-packages\requests\api.py", line 75, in get
    return request('get', url, params=params, **kwargs)
  File "c:\python38\lib\site-packages\requests\api.py", line 61, in request
    return session.request(method=method, url=url, **kwargs)
  File "c:\python38\lib\site-packages\requests\sessions.py", line 542, in request
    resp = self.send(prep, **send_kwargs)
  File "c:\python38\lib\site-packages\requests\sessions.py", line 655, in send
    r = adapter.send(request, **kwargs)
  File "c:\python38\lib\site-packages\requests\adapters.py", line 498, in send
    raise ConnectionError(err, request=request)
requests.exceptions.ConnectionError: ('Connection aborted.', RemoteDisconnected('Remote end closed connection without response'))



  ========= 测试结束 : 20220422_180029 =========


  耗时    : 5.021 秒


  预备执行用例数量 : 2

  实际执行用例数量 : 0

  通过 : 0

  失败 : 0

  异常 : 0

  套件初始化失败 : 1

  套件清除  失败 : 0

  用例初始化失败 : 0

  用例清除  失败 : 0
